{
 "cells": [
  {
   "cell_type": "code",
   "execution_count": null,
   "metadata": {},
   "outputs": [
    {
     "ename": "",
     "evalue": "",
     "output_type": "error",
     "traceback": [
      "\u001b[1;31mFailed to start the Kernel. \n",
      "\u001b[1;31mTraceback (most recent call last):\n",
      "\u001b[1;31m  File \"/usr/local/anaconda3/lib/python3.9/runpy.py\", line 197, in _run_module_as_main\n",
      "\u001b[1;31m    return _run_code(code, main_globals, None,\n",
      "\u001b[1;31m  File \"/usr/local/anaconda3/lib/python3.9/runpy.py\", line 87, in _run_code\n",
      "\u001b[1;31m    exec(code, run_globals)\n",
      "\u001b[1;31m  File \"/usr/local/anaconda3/lib/python3.9/site-packages/ipykernel_launcher.py\", line 15, in <module>\n",
      "\u001b[1;31m    from ipykernel import kernelapp as app\n",
      "\u001b[1;31m  File \"/usr/local/anaconda3/lib/python3.9/site-packages/ipykernel/kernelapp.py\", line 22, in <module>\n",
      "\u001b[1;31m    from IPython.core.application import (\n",
      "\u001b[1;31m  File \"/usr/local/anaconda3/lib/python3.9/site-packages/IPython/__init__.py\", line 51, in <module>\n",
      "\u001b[1;31m    from .core.application import Application\n",
      "\u001b[1;31m  File \"/usr/local/anaconda3/lib/python3.9/site-packages/IPython/core/application.py\", line 27, in <module>\n",
      "\u001b[1;31m    from IPython.core import release, crashhandler\n",
      "\u001b[1;31m  File \"/usr/local/anaconda3/lib/python3.9/site-packages/IPython/core/crashhandler.py\", line 28, in <module>\n",
      "\u001b[1;31m    from IPython.core import ultratb\n",
      "\u001b[1;31m  File \"/usr/local/anaconda3/lib/python3.9/site-packages/IPython/core/ultratb.py\", line 107, in <module>\n",
      "\u001b[1;31m    from IPython.core import debugger\n",
      "\u001b[1;31m  File \"/usr/local/anaconda3/lib/python3.9/site-packages/IPython/core/debugger.py\", line 123, in <module>\n",
      "\u001b[1;31m    from pdb import Pdb as OldPdb\n",
      "\u001b[1;31m  File \"/usr/local/anaconda3/lib/python3.9/pdb.py\", line 77, in <module>\n",
      "\u001b[1;31m    import code\n",
      "\u001b[1;31m  File \"/Users/annika/Documents/education/UvA/Business Analytics/year3/thesis/LLMsForOptimizationModelling/Datasets/NL_4_AlkylationProccess/code.py\", line 55, in <module>\n",
      "\u001b[1;31m    results = solver.solve(model)\n",
      "\u001b[1;31m  File \"/usr/local/anaconda3/lib/python3.9/site-packages/pyomo/opt/base/solvers.py\", line 105, in solve\n",
      "\u001b[1;31m    self._solver_error('solve')\n",
      "\u001b[1;31m  File \"/usr/local/anaconda3/lib/python3.9/site-packages/pyomo/opt/base/solvers.py\", line 122, in _solver_error\n",
      "\u001b[1;31m    raise RuntimeError(\"\"\"Attempting to use an unavailable solver.\n",
      "\u001b[1;31mRuntimeError: Attempting to use an unavailable solver.\n",
      "\u001b[1;31m\n",
      "\u001b[1;31mThe SolverFactory was unable to create the solver \"couenne\"\n",
      "\u001b[1;31mand returned an UnknownSolver object.  This error is raised at the point\n",
      "\u001b[1;31mwhere the UnknownSolver object was used as if it were valid (by calling\n",
      "\u001b[1;31mmethod \"solve\").\n",
      "\u001b[1;31m\n",
      "\u001b[1;31mThe original solver was created with the following parameters:\n",
      "\u001b[1;31m\texecutable: couenne\n",
      "\u001b[1;31m\ttype: couenne\n",
      "\u001b[1;31m\t_args: ()\n",
      "\u001b[1;31m\toptions: {}. \n",
      "\u001b[1;31mView Jupyter <a href='command:jupyter.viewOutput'>log</a> for further details."
     ]
    }
   ],
   "source": [
    "# Costs\n",
    "c1, c2, c3, c4, c5 = 0.63, 5.04, 0.035, 10.0, 3.36\n",
    "\n",
    "# Lower and upper bounds\n",
    "x1_l, x1_u = (0, 2000)\n",
    "x2_l, x2_u = (0, 16000)\n",
    "x3_l, x3_u = (0, 120)\n",
    "x4_l, x4_u = (0, 5000)\n",
    "x5_l, x5_u = (0, 2000)\n",
    "x6_l, x6_u = (85, 93)\n",
    "x7_l, x7_u = (90, 95)\n",
    "x8_l, x8_u = (3, 12)\n",
    "x9_l, x9_u = (1.2, 4)\n",
    "x10_l, x10_u = (145, 162)"
   ]
  },
  {
   "cell_type": "code",
   "execution_count": null,
   "metadata": {},
   "outputs": [
    {
     "ename": "",
     "evalue": "",
     "output_type": "error",
     "traceback": [
      "\u001b[1;31mFailed to start the Kernel. \n",
      "\u001b[1;31mTraceback (most recent call last):\n",
      "\u001b[1;31m  File \"<frozen runpy>\", line 198, in _run_module_as_main\n",
      "\u001b[1;31m  File \"<frozen runpy>\", line 88, in _run_code\n",
      "\u001b[1;31m  File \"/usr/local/anaconda3/envs/maths3/lib/python3.11/site-packages/ipykernel_launcher.py\", line 15, in <module>\n",
      "\u001b[1;31m    from ipykernel import kernelapp as app\n",
      "\u001b[1;31m  File \"/usr/local/anaconda3/envs/maths3/lib/python3.11/site-packages/ipykernel/kernelapp.py\", line 18, in <module>\n",
      "\u001b[1;31m    from IPython.core.application import (\n",
      "\u001b[1;31m  File \"/usr/local/anaconda3/envs/maths3/lib/python3.11/site-packages/IPython/__init__.py\", line 52, in <module>\n",
      "\u001b[1;31m    from .core.application import Application\n",
      "\u001b[1;31m  File \"/usr/local/anaconda3/envs/maths3/lib/python3.11/site-packages/IPython/core/application.py\", line 26, in <module>\n",
      "\u001b[1;31m    from IPython.core import release, crashhandler\n",
      "\u001b[1;31m  File \"/usr/local/anaconda3/envs/maths3/lib/python3.11/site-packages/IPython/core/crashhandler.py\", line 27, in <module>\n",
      "\u001b[1;31m    from IPython.core import ultratb\n",
      "\u001b[1;31m  File \"/usr/local/anaconda3/envs/maths3/lib/python3.11/site-packages/IPython/core/ultratb.py\", line 108, in <module>\n",
      "\u001b[1;31m    from IPython.core import debugger\n",
      "\u001b[1;31m  File \"/usr/local/anaconda3/envs/maths3/lib/python3.11/site-packages/IPython/core/debugger.py\", line 121, in <module>\n",
      "\u001b[1;31m    from pdb import Pdb as OldPdb\n",
      "\u001b[1;31m  File \"/usr/local/anaconda3/envs/maths3/lib/python3.11/pdb.py\", line 77, in <module>\n",
      "\u001b[1;31m    import code\n",
      "\u001b[1;31m  File \"/Users/annika/Documents/education/UvA/Business Analytics/year3/thesis/LLMsForOptimizationModelling/Datasets/NL_4_AlkylationProccess/code.py\", line 55, in <module>\n",
      "\u001b[1;31m    results = solver.solve(model)\n",
      "\u001b[1;31m              ^^^^^^^^^^^^^^^^^^^\n",
      "\u001b[1;31m  File \"/usr/local/anaconda3/envs/maths3/lib/python3.11/site-packages/pyomo/opt/base/solvers.py\", line 99, in solve\n",
      "\u001b[1;31m    self._solver_error('solve')\n",
      "\u001b[1;31m  File \"/usr/local/anaconda3/envs/maths3/lib/python3.11/site-packages/pyomo/opt/base/solvers.py\", line 116, in _solver_error\n",
      "\u001b[1;31m    raise RuntimeError(\n",
      "\u001b[1;31mRuntimeError: Attempting to use an unavailable solver.\n",
      "\u001b[1;31m\n",
      "\u001b[1;31mThe SolverFactory was unable to create the solver \"couenne\"\n",
      "\u001b[1;31mand returned an UnknownSolver object.  This error is raised at the point\n",
      "\u001b[1;31mwhere the UnknownSolver object was used as if it were valid (by calling\n",
      "\u001b[1;31mmethod \"solve\").\n",
      "\u001b[1;31m\n",
      "\u001b[1;31mThe original solver was created with the following parameters:\n",
      "\u001b[1;31m\texecutable: couenne\n",
      "\u001b[1;31m\ttype: couenne\n",
      "\u001b[1;31m\t_args: ()\n",
      "\u001b[1;31m\toptions: {}. \n",
      "\u001b[1;31mView Jupyter <a href='command:jupyter.viewOutput'>log</a> for further details."
     ]
    }
   ],
   "source": [
    "# Alkylation Problem with Couenne\n",
    "import pyomo.environ as pyo\n",
    "\n",
    "# Data\n",
    "x1_l, x1_u = (0, 2000)\n",
    "x2_l, x2_u = (0, 16000)\n",
    "x3_l, x3_u = (0, 120)\n",
    "x4_l, x4_u = (0, 5000)\n",
    "x5_l, x5_u = (0, 2000)\n",
    "x6_l, x6_u = (85, 93)\n",
    "x7_l, x7_u = (90, 95)\n",
    "x8_l, x8_u = (3, 12)\n",
    "x9_l, x9_u = (1.2, 4)\n",
    "x10_l, x10_u = (145, 162)\n",
    "\n",
    "# Create a model object\n",
    "model = pyo.ConcreteModel()\n",
    "\n",
    "# Declare the variables with bounds (assuming bounds x_i^l and x_i^u are defined elsewhere)\n",
    "model.x1 = pyo.Var(within=pyo.NonNegativeReals, bounds=(x1_l, x1_u))\n",
    "model.x2 = pyo.Var(within=pyo.NonNegativeReals, bounds=(x2_l, x2_u))\n",
    "model.x3 = pyo.Var(within=pyo.NonNegativeReals, bounds=(x3_l, x3_u))\n",
    "model.x4 = pyo.Var(within=pyo.NonNegativeReals, bounds=(x4_l, x4_u))\n",
    "model.x5 = pyo.Var(within=pyo.NonNegativeReals, bounds=(x5_l, x5_u))\n",
    "model.x6 = pyo.Var(within=pyo.NonNegativeReals, bounds=(x6_l, x6_u))\n",
    "model.x7 = pyo.Var(within=pyo.NonNegativeReals, bounds=(x7_l, x7_u))\n",
    "model.x8 = pyo.Var(within=pyo.NonNegativeReals, bounds=(x8_l, x8_u))\n",
    "model.x9 = pyo.Var(within=pyo.NonNegativeReals, bounds=(x9_l, x9_u))\n",
    "model.x10 = pyo.Var(within=pyo.NonNegativeReals, bounds=(x10_l, x10_u))\n",
    "\n",
    "# Constants in the objective function and bounds\n",
    "d4_l, d4_u, d7_l, d7_u, d9_l, d9_u, d10_l, d10_u = 98/100, 102/100, 99/100, 101/100, 95/100, 105/100, 9/10, 11/10\n",
    "\n",
    "# Objective function\n",
    "model.objective = pyo.Objective(expr=c1*model.x4*model.x7 - c2*model.x1 - c3*model.x2 - c4*model.x3 - c5*model.x5, sense=pyo.maximize)\n",
    "\n",
    "# Constraints\n",
    "model.constraint1 = pyo.Constraint(expr=(model.x1 * (1.12 + 0.13167 * model.x8 - 0.00667 * model.x8**2)) - d4_l * model.x4 >= 0)\n",
    "model.constraint2 = pyo.Constraint(expr=-(model.x1 * (1.12 + 0.13167 * model.x8 - 0.00667 * model.x8**2)) + d4_u * model.x4 >= 0)\n",
    "model.constraint3 = pyo.Constraint(expr=(86.35 + 1.098 * model.x8 - 0.038 * model.x8**2 + 0.325 * (model.x6 - 89)) - d7_l * model.x7 >= 0)\n",
    "model.constraint4 = pyo.Constraint(expr=-(86.35 + 1.098 * model.x8 - 0.038 * model.x8**2 + 0.325 * (model.x6 - 89)) + d7_u * model.x7 >= 0)\n",
    "model.constraint5 = pyo.Constraint(expr=(35.82 - 0.222 * model.x10) - d9_l * model.x9 >= 0)\n",
    "model.constraint6 = pyo.Constraint(expr=-(35.82 - 0.222 * model.x10) + d9_u * model.x9 >= 0)\n",
    "model.constraint7 = pyo.Constraint(expr=(-133 + 3 * model.x7) - d10_l * model.x10 >= 0)\n",
    "model.constraint8 = pyo.Constraint(expr=-(-133 + 3 * model.x7) + d10_u * model.x10 >= 0)\n",
    "model.constraint9 = pyo.Constraint(expr=1.22 * model.x4 - model.x1 - model.x5 == 0)\n",
    "model.constraint10 = pyo.Constraint(expr=((93000 * model.x3)/(model.x3 * model.x9 + 1000 * model.x3)) - model.x6 == 0)\n",
    "model.constraint11 = pyo.Constraint(expr=((model.x2 + model.x5)/model.x1) - model.x8 == 0)\n",
    "\n",
    "# Solve the model\n",
    "solver=pyo.SolverFactory('couenne')\n",
    "results = solver.solve(model)\n",
    "\n",
    "# Display the results\n",
    "model.pprint()\n",
    "\n",
    "# Display the results\n",
    "print(\"Objective Value:\", round(model.objective(), 2))\n",
    "print(\"X1:\", round(model.x1(), 2))\n",
    "print(\"X2:\", round(model.x2(), 2))\n",
    "print(\"X3:\", round(model.x3(), 2))\n",
    "print(\"X4:\", round(model.x4(), 2))\n",
    "print(\"X5:\", round(model.x5(), 2))\n",
    "print(\"X6:\", round(model.x6(), 2))\n",
    "print(\"X7:\", round(model.x7(), 2))\n",
    "print(\"X8:\", round(model.x8(), 2))\n",
    "print(\"X9:\", round(model.x9(), 2))\n",
    "print(\"X10:\", round(model.x10(), 2))"
   ]
  }
 ],
 "metadata": {
  "kernelspec": {
   "display_name": "maths3",
   "language": "python",
   "name": "python3"
  },
  "language_info": {
   "name": "python",
   "version": "3.9.12"
  }
 },
 "nbformat": 4,
 "nbformat_minor": 2
}
